Workbook

Sheet Assignment_Data7 to 10
A1: Age | B1: Salary | C1: Purchase_Count | D1: Satisfaction_Score | E1: Visit_Frequency | F1: Z score
A2: 56 | B2: 158767 | C2: 17 | D2: 1.9759586 | E2: 7 | F2: =('Assignment_Data7 to 10'!D2-AVERAGE('Assignment_Data7 to 10'!D2:D101))/STDEV('Assignment_Data7 to 10'!D2:D101) -> -0.9901045
A3: 46 | B3: 149375 | C3: 38 | D3: 4.8920422 | E3: 5 | F3: =('Assignment_Data7 to 10'!D3-AVERAGE('Assignment_Data7 to 10'!D3:D102))/STDEV('Assignment_Data7 to 10'!D3:D102) -> 1.4894752
A4: 32 | B4: 161330 | C4: 24 | D4: 2.5723909 | E4: 3 | F4: =('Assignment_Data7 to 10'!D4-AVERAGE('Assignment_Data7 to 10'!D4:D103))/STDEV('Assignment_Data7 to 10'!D4:D103) -> -0.47874099
A5: 60 | B5: 64504 | C5: 5 | D5: 4.5681862 | E5: 12 | F5: =('Assignment_Data7 to 10'!D5-AVERAGE('Assignment_Data7 to 10'!D5:D104))/STDEV('Assignment_Data7 to 10'!D5:D104) -> 1.2262905
A6: 25 | B6: 38986 | C6: 34 | D6: 3.5245545 | E6: 16 | F6: =('Assignment_Data7 to 10'!D6-AVERAGE('Assignment_Data7 to 10'!D6:D105))/STDEV('Assignment_Data7 to 10'!D6:D105) -> 0.34685248
A7: 38 | B7: 86858 | C7: 6 | D7: 4.1792452 | E7: 19 | F7: =('Assignment_Data7 to 10'!D7-AVERAGE('Assignment_Data7 to 10'!D7:D106))/STDEV('Assignment_Data7 to 10'!D7:D106) -> 0.90810624
A8: 56 | B8: 154312 | C8: 22 | D8: 3.0105484 | E8: 5 | F8: =('Assignment_Data7 to 10'!D8-AVERAGE('Assignment_Data7 to 10'!D8:D107))/STDEV('Assignment_Data7 to 10'!D8:D107) -> -0.080447987
A9: 36 | B9: 37666 | C9: 11 | D9: 3.3076155 | E9: 14 | F9: =('Assignment_Data7 to 10'!D9-AVERAGE('Assignment_Data7 to 10'!D9:D108))/STDEV('Assignment_Data7 to 10'!D9:D108) -> 0.17128894
A10: 40 | B10: 63660 | C10: 48 | D10: 2.9700708 | E10: 5 | F10: =('Assignment_Data7 to 10'!D10-AVERAGE('Assignment_Data7 to 10'!D10:D109))/STDEV('Assignment_Data7 to 10'!D10:D109) -> -0.11277555 | I10: Mean
A11: 28 | B11: 159633 | C11: 16 | D11: 1.780972 | E11: 15 | F11: =('Assignment_Data7 to 10'!D11-AVERAGE('Assignment_Data7 to 10'!D11:D110))/STDEV('Assignment_Data7 to 10'!D11:D110) -> -1.111965 | H11: Mean | I11: =AVERAGE(D2:D101) -> 3.1356483
A12: 28 | B12: 51854 | C12: 33 | D12: 3.8898085 | E12: 17 | F12: =('Assignment_Data7 to 10'!D12-AVERAGE('Assignment_Data7 to 10'!D12:D111))/STDEV('Assignment_Data7 to 10'!D12:D111) -> 0.64752973
A13: 41 | B13: 89505 | C13: 9 | D13: 2.1230894 | E13: 14 | F13: =('Assignment_Data7 to 10'!D13-AVERAGE('Assignment_Data7 to 10'!D13:D112))/STDEV('Assignment_Data7 to 10'!D13:D112) -> -0.82821724 | H13: STDEV.S | I13: =_xlfn.STDEV.S(D2:D101) -> 1.1712801
A14: 53 | B14: 129488 | C14: 6 | D14: 1.0972639 | E14: 5 | F14: =('Assignment_Data7 to 10'!D14-AVERAGE('Assignment_Data7 to 10'!D14:D113))/STDEV('Assignment_Data7 to 10'!D14:D113) -> -1.6945111
A15: 57 | B15: 47662 | C15: 16 | D15: 3.5818892 | E15: 12 | F15: =('Assignment_Data7 to 10'!D15-AVERAGE('Assignment_Data7 to 10'!D15:D114))/STDEV('Assignment_Data7 to 10'!D15:D114) -> 0.36911518 | H15: Lower limit | I15: =I11-(2*I13) -> 0.79308804
A16: 41 | B16: 33392 | C16: 29 | D16: 1.7084427 | E16: 16 | F16: =('Assignment_Data7 to 10'!D16-AVERAGE('Assignment_Data7 to 10'!D16:D115))/STDEV('Assignment_Data7 to 10'!D16:D115) -> -1.205737
A17: 20 | B17: 55535 | C17: 3 | D17: 4.7618343 | E17: 16 | F17: =('Assignment_Data7 to 10'!D17-AVERAGE('Assignment_Data7 to 10'!D17:D116))/STDEV('Assignment_Data7 to 10'!D17:D116) -> 1.354547 | H17: Upper limit | I17: =I11+(2*I13) -> 5.4782086
A18: 39 | B18: 138569 | C18: 20 | D18: 4.8157143 | E18: 7 | F18: =('Assignment_Data7 to 10'!D18-AVERAGE('Assignment_Data7 to 10'!D18:D117))/STDEV('Assignment_Data7 to 10'!D18:D117) -> 1.4235272
A19: 19 | B19: 77256 | C19: 36 | D19: 4.6594576 | E19: 4 | F19: =('Assignment_Data7 to 10'!D19-AVERAGE('Assignment_Data7 to 10'!D19:D118))/STDEV('Assignment_Data7 to 10'!D19:D118) -> 1.3165313
A20: 41 | B20: 114135 | C20: 19 | D20: 2.4806348 | E20: 1 | F20: =('Assignment_Data7 to 10'!D20-AVERAGE('Assignment_Data7 to 10'!D20:D119))/STDEV('Assignment_Data7 to 10'!D20:D119) -> -0.53094819
A21: 61 | B21: 152478 | C21: 26 | D21: 1.0618265 | E21: 5 | F21: =('Assignment_Data7 to 10'!D21-AVERAGE('Assignment_Data7 to 10'!D21:D120))/STDEV('Assignment_Data7 to 10'!D21:D120) -> -1.7472846
A22: 47 | B22: 60222 | C22: 3 | D22: 4.7132743 | E22: 10 | F22: =('Assignment_Data7 to 10'!D22-AVERAGE('Assignment_Data7 to 10'!D22:D121))/STDEV('Assignment_Data7 to 10'!D22:D121) -> 1.3687447
A23: 55 | B23: 102373 | C23: 19 | D23: 2.7127366 | E23: 5 | F23: =('Assignment_Data7 to 10'!D23-AVERAGE('Assignment_Data7 to 10'!D23:D122))/STDEV('Assignment_Data7 to 10'!D23:D122) -> -0.34818783
A24: 19 | B24: 148684 | C24: 20 | D24: 4.8666193 | E24: 4 | F24: =('Assignment_Data7 to 10'!D24-AVERAGE('Assignment_Data7 to 10'!D24:D123))/STDEV('Assignment_Data7 to 10'!D24:D123) -> 1.5145951
A25: 38 | B25: 35965 | C25: 32 | D25: 4.8544799 | E25: 2 | F25: =('Assignment_Data7 to 10'!D25-AVERAGE('Assignment_Data7 to 10'!D25:D124))/STDEV('Assignment_Data7 to 10'!D25:D124) -> 1.537199
A26: 50 | B26: 49538 | C26: 7 | D26: 4.4120378 | E26: 10 | F26: =('Assignment_Data7 to 10'!D26-AVERAGE('Assignment_Data7 to 10'!D26:D125))/STDEV('Assignment_Data7 to 10'!D26:D125) -> 1.1819269
A27: 29 | B27: 133066 | C27: 41 | D27: 2.1777956 | E27: 19 | F27: =('Assignment_Data7 to 10'!D27-AVERAGE('Assignment_Data7 to 10'!D27:D126))/STDEV('Assignment_Data7 to 10'!D27:D126) -> -0.77481088
A28: 39 | B28: 138252 | C28: 33 | D28: 2.5403909 | E28: 1 | F28: =('Assignment_Data7 to 10'!D28-AVERAGE('Assignment_Data7 to 10'!D28:D127))/STDEV('Assignment_Data7 to 10'!D28:D127) -> -0.46337547
A29: 61 | B29: 164182 | C29: 40 | D29: 4.4045467 | E29: 5 | F29: =('Assignment_Data7 to 10'!D29-AVERAGE('Assignment_Data7 to 10'!D29:D128))/STDEV('Assignment_Data7 to 10'!D29:D128) -> 1.1681286
... A88: 43 | B88: 179736 | C88: 33 | D88: 1.3138255 | E88: 9 | F88: =('Assignment_Data7 to 10'!D88-AVERAGE('Assignment_Data7 to 10'!D88:D187))/STDEV('Assignment_Data7 to 10'!D88:D187) -> -1.2343182
A89: 42 | B89: 92172 | C89: 14 | D89: 1.101403 | E89: 17 | F89: =('Assignment_Data7 to 10'!D89-AVERAGE('Assignment_Data7 to 10'!D89:D188))/STDEV('Assignment_Data7 to 10'!D89:D188) -> -1.5332481 | J89: =4088/100 -> 40.88
A90: 62 | B90: 118264 | C90: 21 | D90: 4.8505937 | E90: 17 | F90: =('Assignment_Data7 to 10'!D90-AVERAGE('Assignment_Data7 to 10'!D90:D189))/STDEV('Assignment_Data7 to 10'!D90:D189) -> 1.3878732
A91: 58 | B91: 51736 | C91: 48 | D91: 4.3439205 | E91: 16 | F91: =('Assignment_Data7 to 10'!D91-AVERAGE('Assignment_Data7 to 10'!D91:D190))/STDEV('Assignment_Data7 to 10'!D91:D190) -> 1.1494833
A92: 46 | B92: 137859 | C92: 20 | D92: 3.7838968 | E92: 13 | F92: =('Assignment_Data7 to 10'!D92-AVERAGE('Assignment_Data7 to 10'!D92:D191))/STDEV('Assignment_Data7 to 10'!D92:D191) -> 0.78087632
A93: 32 | B93: 137181 | C93: 8 | D93: 2.6358118 | E93: 19 | F93: =('Assignment_Data7 to 10'!D93-AVERAGE('Assignment_Data7 to 10'!D93:D192))/STDEV('Assignment_Data7 to 10'!D93:D192) -> -0.18780756
A94: 62 | B94: 156926 | C94: 7 | D94: 1.6931773 | E94: 17 | F94: =('Assignment_Data7 to 10'!D94-AVERAGE('Assignment_Data7 to 10'!D94:D193))/STDEV('Assignment_Data7 to 10'!D94:D193) -> -0.99768378
A95: 18 | B95: 115084 | C95: 3 | D95: 1.6257482 | E95: 4 | F95: =('Assignment_Data7 to 10'!D95-AVERAGE('Assignment_Data7 to 10'!D95:D194))/STDEV('Assignment_Data7 to 10'!D95:D194) -> -1.211372
A96: 42 | B96: 32392 | C96: 17 | D96: 2.0009716 | E96: 12 | F96: =('Assignment_Data7 to 10'!D96-AVERAGE('Assignment_Data7 to 10'!D96:D195))/STDEV('Assignment_Data7 to 10'!D96:D195) -> -1.178408
A97: 24 | B97: 80680 | C97: 33 | D97: 3.1969067 | E97: 9 | F97: =('Assignment_Data7 to 10'!D97-AVERAGE('Assignment_Data7 to 10'!D97:D196))/STDEV('Assignment_Data7 to 10'!D97:D196) -> -0.33510405
A98: 26 | B98: 75859 | C98: 48 | D98: 3.8583837 | E98: 19 | F98: =('Assignment_Data7 to 10'!D98-AVERAGE('Assignment_Data7 to 10'!D98:D197))/STDEV('Assignment_Data7 to 10'!D98:D197) -> 0.22263471
...

Sheet Stastics question

Sheet Stastics assignment
A2: Q-1 | B2: Calculate the mean, median, and mode of 'Age'. | C2: Mean | D2: Median | F2: Mode
C3: =AVERAGE('Assignment_Data7 to 10'!A:A) -> 40.88 | D3: =MEDIAN('Assignment_Data7 to 10'!A2:A101) -> 41 | F3: =MODE('Assignment_Data7 to 10'!A2:A101) -> 61
A5: Q-2 | B5: Find the standard deviation and variance of 'Salary'. | C5: Standard deviation | D5: Variance
C6: =_xlfn.STDEV.S('Assignment_Data7 to 10'!B:B) -> 44418.086 | D6: =VAR('Assignment_Data7 to 10'!B:B) -> 1.9729664e+09
A8: Q-3 | B8: Compute the skewness and kurtosis of 'Purchase_Count'. | C8: Skewness | D8: Kurtosis
C9: =SKEW('Assignment_Data7 to 10'!C:C) -> 0.048663602 | D9: =KURT('Assignment_Data7 to 10'!C:C) -> -1.0551591
A11: Q-4 | B11: What is the correlation between 'Salary' and 'Satisfaction_Score'? | C11: Correction between salary & satisfaction score
C12: =CORREL('Assignment_Data7 to 10'!B:B,'Assignment_Data7 to 10'!D:D) -> -0.16429646
A14: Q-5 | B14: Get the summary statistics (count, mean, std, min, 25%, 50%, 75%, max) for every column. | C14: Refer sheet Q-5 sheet
A17: Q-6 | B17: Plot the histogram of 'Visit_Frequency' and comment on its skewness. | C17: Refer sheet Q-6 Sheet
A19: Q-7 | B19: Identify if 'Satisfaction_Score' has any outliers using standard deviation method. | C19: Using Standard deviation method lower limit is 0.79 and upper limit is 5.48 all scores fall within this range therefore there are no outliers in this data set | D19: Mean | E19: 3.1356483 | F19: STDEV.S | G19: 1.1712801 | H19: Lower limit | I19: 0.79308804 | J19: Upper limit | K19: 5.4782086
A21: Q-8 | B21: Calculate the coefficient of variation for 'Salary'. | C21: =STDEV('Assignment_Data7 to 10'!B2:B101)/AVERAGE('Assignment_Data7 to 10'!B2:B101) -> 0.40630692
A23: Q-9 | B23: Find the interquartile range (IQR) for 'Purchase_Count'. | C23: =F24-D24 -> 21.5 | D23: Q1 | F23: Q3
D24: =QUARTILE('Assignment_Data7 to 10'!C:C,1) -> 13.5 | F24: =QUARTILE('Assignment_Data7 to 10'!C:C,3) -> 35
A26: Q-10 | B26: Compute the Pearson correlation matrix for the entire dataset. | C26: Refer sheet Q-10 Sheet
A28: Q-11 | B28: Calculate the range (max - min) for the 'Age' and 'Salary' columns. | C28: Age | D28: Salary
C29: {=MAX('Assignment_Data7 to 10'!A2:A101-MIN('Assignment_Data7 to 10'!A2:A101))} -> 46 | D29: {=MAX('Assignment_Data7 to 10'!B2:B101-MIN('Assignment_Data7 to 10'!B2:B101))} -> 152043
A31: Q-12 | B31: Determine the percentile ranks for 'Purchase_Count' at 25%, 50%, and 75%. | C31: 0.25 | D31: 0.5 | F31: 0.75
C32: =PERCENTILE('Assignment_Data7 to 10'!C2:C101,0.25) -> 13.5 | D32: =PERCENTILE('Assignment_Data7 to 10'!C2:C101,0.5) -> 24 | F32: =PERCENTILE('Assignment_Data7 to 10'!C2:C101,0.75) -> 35
A34: Q-13 | B34: Find the covariance between 'Salary' and 'Visit_Frequency'. | C34: Covariance
C35: =_xlfn.COVARIANCE.P('Assignment_Data7 to 10'!B2:B101,'Assignment_Data7 to 10'!E2:E101) -> -20024.91
A37: Q-14 | B37: Check if 'Salary' follows a normal distribution using skewness and kurtosis values. | C37: Skewness | D37: Kurtosis
C38: =SKEW('Assignment_Data7 to 10'!B2:B101) -> -0.25307872 | D38: =KURT('Assignment_Data7 to 10'!B2:B101) -> -1.2236235
C39: No | D39: No
A41: Q-15 | B41: Calculate the z-scores for 'Satisfaction_Score' and identify any data points beyond ±3. | C41: No

Sheet Q-5
A1: Get the summary statistics (count, mean, std, min, 25%, 50%, 75%, max) for every column.
A2: Age | C2: Salary | E2: Purchase_Count | G2: Satisfaction_Score | I2: Visit_Frequency
A4: Mean | B4: 40.88 | C4: Mean | D4: 109321.51 | E4: Mean | F4: 24.47 | G4: Mean | H4: 3.1356483 | I4: Mean | J4: 9.96
A5: Standard Error | B5: 1.399082 | C5: Standard Error | D5: 4441.8086 | E5: Standard Error | F5: 1.3994555 | G5: Standard Error | H5: 0.11712801 | I5: Standard Error | J5: 0.58204099
A6: Median | B6: 41 | C6: Median | D6: 118025.5 | E6: Median | F6: 24 | G6: Median | H6: 3.1837426 | I6: Median | J6: 10
A7: Mode | B7: 61 | C7: Mode | D7: #N/A | E7: Mode | F7: 48 | G7: Mode | H7: #N/A | I7: Mode | J7: 5
A8: Standard Deviation | B8: 13.99082 | C8: Standard Deviation | D8: 44418.086 | E8: Standard Deviation | F8: 13.994555 | G8: Standard Deviation | H8: 1.1712801 | I8: Standard Deviation | J8: 5.8204099
A9: Sample Variance | B9: 195.74303 | C9: Sample Variance | D9: 1.9729664e+09 | E9: Sample Variance | F9: 195.84758 | G9: Sample Variance | H9: 1.3718971 | I9: Sample Variance | J9: 33.877172
A10: Kurtosis | B10: -1.1665489 | C10: Kurtosis | D10: -1.2236235 | E10: Kurtosis | F10: -1.0551591 | G10: Kurtosis | H10: -1.1378841 | I10: Kurtosis | J10: -1.3664911
A11: Skewness | B11: 0.079166331 | C11: Skewness | D11: -0.25307872 | E11: Skewness | F11: 0.048663602 | G11: Skewness | H11: -0.16614507 | I11: Skewness | J11: 0.037765579
A12: Range | B12: 46 | C12: Range | D12: 152043 | E12: Range | F12: 48 | G12: Range | H12: 3.8983889 | I12: Range | J12: 18
A13: Minimum | B13: 18 | C13: Minimum | D13: 27693 | E13: Minimum | F13: 1 | G13: Minimum | H13: 1.0618265 | I13: Minimum | J13: 1
A14: Maximum | B14: 64 | C14: Maximum | D14: 179736 | E14: Maximum | F14: 49 | G14: Maximum | H14: 4.9602154 | I14: Maximum | J14: 19
A15: Sum | B15: 4088 | C15: Sum | D15: 10932151 | E15: Sum | F15: 2447 | G15: Sum | H15: 313.56483 | I15: Sum | J15: 996
A16: Count | B16: 100 | C16: Count | D16: 100 | E16: Count | F16: 100 | G16: Count | H16: 100 | I16: Count | J16: 100
C20: 0.25 | D20: =QUARTILE('Assignment_Data7 to 10'!A2:A101,1) -> 30.5
C21: 0.5 | D21: =QUARTILE('Assignment_Data7 to 10'!A2:A101,2) -> 41
C22: 0.75 | D22: =QUARTILE('Assignment_Data7 to 10'!A2:A101,3) -> 53.25

Sheet Q-6
A1: Bin | B1: Frequency
A2: 1 | B2: 6
A3: 2.8 | B3: 4
A4: 4.6 | B4: 15
A5: 6.4 | B5: 10
A6: 8.2 | B6: 7
A7: 10 | B7: 10
A8: 11.8 | B8: 3
A9: 13.6 | B9: 14
A10: 15.4 | B10: 4
A11: 17.2 | B11: 16
A12: More | B12: 11
D15: Skewness | E15: Histogram of visit shows right skewed

Sheet Q-10
B1: 56 | C1: 158767 | D1: 17 | E1: 1.9759586 | F1: 7 | G1: -0.9901045
A2: 56 | B2: 1
A3: 158767 | B3: -0.03030504 | C3: 1
A4: 17 | B4: 0.067657804 | C4: 0.0045417185 | D4: 1
A5: 1.9759586 | B5: -0.095718362 | C5: -0.15480394 | D5: 0.019659927 | E5: 1
A6: 7 | B6: -0.0067815139 | C6: -0.073021545 | D6: -0.16507364 | E6: 0.083592241 | F6: 1
A7: -0.9901045 | B7: -0.10847765 | C7: -0.14701982 | D7: 0.021396542 | E7: 0.97912515 | F7: 0.091968248 | G7: 1

Sheet Pivot assignment
A1: Create a pivot table to find the average Salary by each Category (group by Age groups if preferred).
A3: Use a pivot table to sum the Purchase_Count for each Satisfaction_Score value.
A5: Build a pivot table to show the count of records per Visit_Frequency value.
A7: Generate a pivot table that shows the minimum, maximum, and average Salary per Age group (e.g., 18-25, 26-35, etc.).
A9: Create a pivot table to display the total Purchase_Count for each distinct Salary range bucket (e.g., 25k-50k, 50k-75k, etc.).

Sheet Avg Salary acc to age
A3: Row Labels | B3: Average of Salary
A4: 18-24 | B4: 117521.93
A5: 25-31 | B5: 101394
A6: 32-38 | B6: 102108.75
A7: 39-45 | B7: 113776.63
A8: 46-52 | B8: 116505.25
A9: 53-59 | B9: 109806.5
A10: 60-66 | B10: 106069.79
A11: Grand Total | B11: 109321.51

Sheet Satisfaction -Score Value
A3: Row Labels | B3: Sum of Purchase_Count
A4: 1.0618265 | B4: 26
A5: 1.0972639 | B5: 6
A6: 1.101403 | B6: 14
A7: 1.122001 | B7: 8
A8: 1.1437691 | B8: 24
A9: 1.1493928 | B9: 36
A10: 1.2067269 | B10: 29
A11: 1.3138255 | B11: 33
A12: 1.3413899 | B12: 25
A13: 1.3759278 | B13: 3
A14: 1.388706 | B14: 25
A15: 1.5082421 | B15: 20
... A103: 4.9602154 | B103: 31
A104: Grand Total | B104: 2447

Sheet Visit per frequency  Records
A3: Row Labels | B3: Count of Visit_Frequency
A4: 1 | B4: 6
A5: 2 | B5: 4
A6: 3 | B6: 7
A7: 4 | B7: 8
A8: 5 | B8: 10
A9: 7 | B9: 5
A10: 8 | B10: 2
A11: 9 | B11: 5
A12: 10 | B12: 5
A13: 11 | B13: 3
A14: 12 | B14: 9
A15: 13 | B15: 5
... A21: 19 | B21: 7
A22: Grand Total | B22: 100

Sheet Min Ma Avg Salary By Age Group
A3: Row Labels | B3: Sum of Salary | C3: Max of Salary2 | D3: Min of Salary3
A4: 18-24 | B4: 1762829 | C4: 178371 | D4: 48419
A5: 25-31 | B5: 1419516 | C5: 159633 | D5: 38986
A6: 32-38 | B6: 1633740 | C6: 174213 | D6: 35965
A7: 39-45 | B7: 2161756 | C7: 179736 | D7: 32392
A8: 46-52 | B8: 932042 | C8: 177906 | D8: 28748
A9: 53-59 | B9: 1537291 | C9: 171779 | D9: 47662
A10: 60-66 | B10: 1484977 | C10: 164182 | D10: 27693
A11: Grand Total | B11: 10932151 | C11: 179736 | D11: 27693

Sheet Salary Range Purchase Count
A3: Row Labels | B3: Sum of Purchase_Count
A4: 25000-49999 | B4: 385
A5: 50000-74999 | B5: 227
A6: 75000-99999 | B6: 460
A7: 100000-124999 | B7: 254
A8: 125000-149999 | B8: 565
A9: 150000-174999 | B9: 430
A10: 175000-200000 | B10: 126
A11: Grand Total | B11: 2447
